//
//  ContinuationTests.swift
//  ReallyLazySequencesTests
//
//  Created by Van Simmons on 8/15/18.
//  Copyright Â© 2018 ComputeCycles, LLC. All rights reserved.
//

import XCTest
@testable import ReallyLazySequences

class ContinuationTests: XCTestCase {

    override func setUp() {
        // Put setup code here. This method is called before the invocation of each test method in the class.
    }

    override func tearDown() {
        // Put teardown code here. This method is called after the invocation of each test method in the class.
    }

    enum ReallyLazySequenceError: Error {
        case isComplete
        case nonPushable
        case noListeners
        
        var description: String {
            switch self {
            case .isComplete:
                return "ReallyLazySequence has already completed.  Pushes not allowed"
            case .nonPushable:
                return "push may only be called on Sequences which are NOT already attached to producers"
            case .noListeners:
                return "No listeners available for producer to produce into"
            }
        }
    }

    func testNonThrowingChaining() {
        let expectation = self.expectation(description: "Complete Path 0 processing")
        let expectation0 = self.expectation(description: "Complete Path 1 processing")
        let expectation1 = self.expectation(description: "Complete Path 2 processing")
        var fulfillCount = 0
        
        let continuation1 = {() -> ContinuationResult in
            XCTAssertTrue(fulfillCount == 0, "Messages in wrong order at continuation 1")
            fulfillCount += 1
            expectation.fulfill()
            return ContinuationResult.done
        }
        let continuation1a = { () -> ContinuationResult in
            XCTAssertTrue(fulfillCount == 1, "Messages in wrong order at continuation 2a")
            fulfillCount += 1
            expectation0.fulfill()
            return ContinuationResult.done
        }
        let continuation2 = { ContinuationResult.more(continuation1) }
        let continuation2a = { () -> ContinuationResult in ContinuationResult.more(continuation1a)}
        let continuation3 = { ContinuationResult.afterThen(.more(continuation2), .more(continuation2a)) }
        let continuation4 = { ContinuationResult.more(continuation3) }
        let continuation4a = { () -> ContinuationResult in
            XCTAssertTrue(fulfillCount == 2, "Messages in wrong order at continuation 4a")
            fulfillCount += 1
            expectation1.fulfill()
            return ContinuationResult.done
        }
        let continuation5 = { ContinuationResult.afterThen(.more(continuation4), .more(continuation4a)) }
        let continuation6 = { ContinuationResult.more(continuation5) }
        let continuation7 = { ContinuationResult.more(continuation6) }
        let _ = ContinuationResult.complete(.more(continuation7))
        waitForExpectations(timeout: 10.0) { (error) in XCTAssertNil(error, "Timeout waiting for completion") }
    }

    enum ChainingTestError: Error {
        case context(Continuation) // includes the downstream continuation so that it can be invoked
        case throwingContext(ThrowingContinuation)
    }

    func testErrorChaining() {
        let expectation = self.expectation(description: "Complete Path 0 processing")
        let expectation0 = self.expectation(description: "Complete Path 1 processing")
        let expectation1 = self.expectation(description: "Complete Path 2 processing")
        var fulfillCount = 0
        
        let continuation1 = { () -> ContinuationResult in
            XCTAssertTrue(fulfillCount == 0, "Messages in wrong order at continuation 1")
            fulfillCount += 1
            expectation.fulfill()
            return ContinuationResult.done
        }
        let continuation1a = { () -> ContinuationResult in
            XCTAssertTrue(fulfillCount == 1, "Messages in wrong order at continuation 2a")
            fulfillCount += 1
            expectation0.fulfill()
            return ContinuationResult.done
        }
        let continuation2 = { () throws -> ContinuationResult in
            throw ChainingTestError.context(continuation1)
        }
        let continuation2a = { () -> ContinuationResult in ContinuationResult.more(continuation1a) }
        let continuation3 = { ContinuationResult.afterThen(.moreThrows(continuation2), .more(continuation2a)) }
        let continuation4 = { ContinuationResult.more(continuation3) }
        let continuation4a = { () -> ContinuationResult in
            XCTAssertTrue(fulfillCount == 2, "Messages in wrong order at continuation 4a")
            fulfillCount += 1
            expectation1.fulfill()
            return ContinuationResult.done
        }
        let continuation5 = { ContinuationResult.afterThen(.more(continuation4), .more(continuation4a)) }
        let continuation6 = { ContinuationResult.more(continuation5) }
        let continuation7 = { ContinuationResult.more(continuation6) }
        
        // Attach an error handler that will active in continuation2, i.e. 5 levels away, all processing
        // should continue normally and all expectations should still fulfill
        let _ = ContinuationResult.complete(.more(continuation7)) { (error: Error) -> ContinuationResult in
            guard let error = error as? ChainingTestError else { return .done }
            switch error {
            case .context(let continuation):
                return .more(continuation)
            case .throwingContext(let continuation):
                return .moreThrows(continuation)
            }
        }
        
        waitForExpectations(timeout: 10.0) { (error) in XCTAssertNil(error, "Timeout waiting for completion") }
    }
}
